<?xml version="1.0"?>

<robot name="nalug_robot">
    <link name="base_link">
        <visual>
            <origin rpy="0 0 0" xyz="0 0 0.15" />
            <geometry>
                <cylinder  length="0.3" radius="0.1" />
            </geometry>
            <material name="blue">
                <color rgba="0 0 1 1" />
            </material>
        </visual>
    </link>
    <link name="link1">
        <visual>
            <origin rpy="0 0 0" xyz="0 0 0.25" />
            <geometry>
                <cylinder  length="0.5" radius="0.05" />
            </geometry>
            <material name="yellow">
                <color rgba="1 1 0 1" />
            </material>
        </visual>
    </link>
    <joint name="joint1" type="continuous">
        <axis xyz="0 1 0"/>
        <parent link="base_link"/>
        <child link="link1" />
        <origin rpy="1.57 0 0" xyz="0 0 0.3" />
    </joint>
    <link name="link2">
        <visual>
            <origin rpy="0 0 0" xyz="0 0 0.25" />
            <geometry>
                <cylinder  length="0.5" radius="0.05" />
            </geometry>
            <material name="yellow">
                <color rgba="1 1 0 1" />
            </material>
        </visual>
    </link>
    <joint name="joint2" type="continuous">
        <axis xyz="0 1 0"/>
        <parent link="link1"/>
        <child link="link2" />
        <origin rpy="0 0 0" xyz="0 0 0.5" />
    </joint>
</robot>